<?xml version="1.0"?>
<robot name="simple_robot_path_planning" xmlns:xacro="http://www.ros.org/wiki/xacro">

    <!-- if modifications are made to this file, update the simple_robot.urdf file with the following command:

    rosrun xacro xacro simple_robot_path_planning.xacro > simple_robot_path_planning.urdf

    -->

    <xacro:property name="PI" value="3.1415926535897931"/>
    <!-- Import all Gazebo-customization elements, including Gazebo colors -->
    <xacro:include filename="$(find simple_robot_path_planning)/urdf/simple_robot_path_planning.gazebo" />
    <!-- Import Rviz colors -->
    <xacro:include filename="$(find simple_robot_path_planning)/urdf/materials.xacro" />

    <xacro:simple_robot_path_planning_gazebo />

  <!--Interial macros-->
  <xacro:macro name="cylinder_inertia" params="m r h">
    <inertial>
      <mass value="${m}"/>
      <inertia ixx="${m*(3*r*r+h*h)/12}" ixy = "0" ixz = "0" iyy="${m*(3*r*r+h*h)/12}" iyz = "0" izz="${m*r*r/2}"/> 
    </inertial>
  </xacro:macro>

  <xacro:macro name="box_inertia" params="m w h d">
    <inertial>
      <mass value="${m}"/>
      <inertia ixx="${m / 12.0 * (d*d + h*h)}" ixy="0.0" ixz="0.0" iyy="${m / 12.0 * (w*w + h*h)}" iyz="0.0" izz="${m / 12.0 * (w*w + d*d)}"/>
    </inertial>
  </xacro:macro>

  <xacro:macro name="sphere_inertia" params="m r">
    <inertial>
      <mass value="${m}"/>
      <inertia ixx="${2.0*m*(r*r)/5.0}" ixy="0.0" ixz="0.0" iyy="${2.0*m*(r*r)/5.0}" iyz="0.0" izz="${2.0*m*(r*r)/5.0}"/>
    </inertial>
  </xacro:macro>

  <xacro:macro name="sliding_macro">
<surface>
 <friction>
 <ode>
 <mu>"0"</mu>
 <mu2>"0"</mu2>
 <slip1>"1.0"</slip1>
 <slip2>"1.0"</slip2>
  	  <maxVel>10.0</maxVel>
	  <minDepth>0.001</minDepth>
 </ode>
 </friction>
 </surface>
  </xacro:macro>
  
  <xacro:macro name="non_sliding_macro">
<surface>
 <friction>
 <ode>
 <mu>"100000.0"</mu>
 <mu2>"100000.0"</mu2>
 <slip1>"0.0"</slip1>
 <slip2>"0.0"</slip2>
 	  <maxVel>10.0</maxVel>
	  <minDepth>0.001</minDepth>
 </ode>
 </friction>
 </surface>
  </xacro:macro>  

    <static>false</static>

    <!-- Start of Links - first link must be a non-inertial link -->
    <link name="base_link">
    </link>

    <link name="chassis">
        <inertial>
	<mass value="20"/>
	<inertia ixx=".1" ixy="0.0" ixz="0.0" iyy=".1" iyz="0.0" izz=".1"/>
        </inertial>
        <collision name='collision'>
            <geometry>
                <box size=".3 .2 .1" />
            </geometry>          
        </collision>
        <visual name='visual'>
            <geometry>
                <box size=".3 .2 .1" />
            </geometry>
            <material name="orange" />
        </visual>
    </link>

    <link name="castor1">
	<xacro:sphere_inertia m="1" r=".044"/>
        <collision name='collision'>
            <geometry>
                <sphere radius=".044" />
            </geometry>
            <xacro:sliding_macro/>
        </collision>
        <visual name='visual'>
            <geometry>
                <sphere radius=".044" />
            </geometry>
        </visual>
    </link>
    
    <link name="castor2">
	<xacro:sphere_inertia m="1" r=".044"/>
        <collision name='collision'>
            <geometry>
                <sphere radius=".044" />
            </geometry>
            <xacro:sliding_macro/>
        </collision>
        <visual name='visual'>
            <geometry>
                <sphere radius=".044" />
            </geometry>
        </visual>
    </link>    

    <link name="left_wheel">
        <inertial>
            <mass value=".15"/>
            <inertia ixx="1" ixy="0.0" ixz="0.0" iyy="1" iyz="0.0" izz="1"/>
        </inertial>
        <pose>0.1 0.13 0.1 0 1.5707 1.5707</pose>
        <collision name='collision'>
            <geometry>
                <cylinder radius='.1' length='.015'/>
            </geometry>   
            <xacro:non_sliding_macro/>            
        </collision>
        <visual name='visual'>
            <geometry>
                <cylinder radius='.1' length='.015'/>
            </geometry>
	    <material name="green" />
        </visual>
    </link>

    <link name="right_wheel">
        <inertial>
            <mass value=".15"/>
            <inertia ixx="1" ixy="0.0" ixz="0.0" iyy="1" iyz="0.0" izz="1"/>
        </inertial>
        <pose>0.1 0.13 0.1 0 1.5707 1.5707</pose>
        <collision name='collision'>
            <geometry>
                <cylinder radius='.1' length='.015'/>
            </geometry>          
            <xacro:non_sliding_macro/>                 
        </collision>
        <visual name='visual'>
            <geometry>
                <cylinder radius='.1' length='.015'/>
            </geometry>
	    <material name="red" />
        </visual>
    </link>

  <!-- Hokuyo Laser -->
  <link name="hokuyo_link">
    <collision>
      <origin xyz="0 0 0" rpy="0 0 0"/>
      <geometry>
    <box size="0.1 0.1 0.1"/>
      </geometry>
    </collision>

    <visual>
      <origin xyz="0 0 0" rpy="0 0 0"/>
      <geometry>
        <mesh filename="package://simple_robot_path_planning/meshes/hokuyo.dae"/>
      </geometry>
    </visual>

    <inertial>
      <mass value="1e-5" />
      <origin xyz="0 0 0" rpy="0 0 0"/>
      <inertia ixx="1e-6" ixy="0" ixz="0" iyy="1e-6" iyz="0" izz="1e-6" />
    </inertial>
  </link>



    <!-- Start of Joints - connecting all links together -->

<joint name="hokuyo_joint" type="fixed">
    <axis xyz="0 1 0" />
    <origin xyz="0.1 0 .1" rpy="0 0 0"/>
    <parent link="base_link"/>
    <child link="hokuyo_link"/>
        <dynamics damping="0.7"/>
  </joint>

    <joint name="joint0" type="fixed">
        <parent link="base_link"/>
        <child link="chassis"/>
        <origin xyz="0 0 0" rpy="0 0 0"/>
        <axis xyz="0 1 0"/>
        <dynamics damping="0.7"/>
    </joint>

    <joint name="joint1" type="fixed">
        <parent link="chassis"/>
        <child link="castor1"/>
        <origin xyz=".075 0 -.055" rpy="0 0 0"/>
        <axis xyz="0 1 0"/>
        <dynamics damping="0.7"/>
    </joint>

    <joint name="joint2" type="fixed">
        <parent link="chassis"/>
        <child link="castor2"/>
        <origin xyz="-.075 0 -.055" rpy="0 0 0"/>
        <axis xyz="0 1 0"/>
        <dynamics damping="0.7"/>
    </joint>


    <joint type="continuous" name="wheel_right_joint">
        <parent link="chassis"/>
        <child link="left_wheel"/>
        <origin xyz="-0.0 -0.13 0" rpy="${PI} -1.5707 1.5707"/>
        <axis xyz="0 0 1"/>
        <dynamics damping="0.1" friction=".1"/>
        <limit effort="30" velocity="30.0" />
        <safety_controller k_velocity="10" k_position="0" soft_lower_limit="0" soft_upper_limit="0" />
    </joint>

    <joint type="continuous" name="wheel_left_joint">
        <parent link="chassis"/>
        <child link="right_wheel"/>
        <origin xyz="-0.0 0.13 0" rpy="${PI} -1.5707 1.5707"/>
        <axis xyz="0 0 1"/>
        <dynamics damping="0.1" friction=".1"/>
        <limit effort="30" velocity="30.0" />
        <safety_controller k_velocity="10" k_position="0" soft_lower_limit="0" soft_upper_limit="0" />
    </joint>

    <!-- Transmissions are where the ros_controller interacts -->

    <transmission name="left_wheel_transmission">
        <type>transmission_interface/SimpleTransmission</type>
        <joint name="wheel_left_joint">
            <hardwareInterface>hardware_interface/VelocityJointInterface</hardwareInterface>
        </joint>
        <actuator name="left_wheel_actuator">
            <mechanicalReduction>1</mechanicalReduction>
            <hardwareInterface>VelocityJointInterface</hardwareInterface>
        </actuator>
    </transmission>

    <transmission name="right_wheel_transmission">
        <type>transmission_interface/SimpleTransmission</type>
        <joint name="wheel_right_joint">
            <hardwareInterface>hardware_interface/VelocityJointInterface</hardwareInterface>
        </joint>
        <actuator name="right_wheel_actuator">
            <mechanicalReduction>1</mechanicalReduction>
            <hardwareInterface>VelocityJointInterface</hardwareInterface>
        </actuator>
    </transmission>
</robot>
